<mujoco>
    <compiler inertiafromgeom="true" angle="degree" coordinate="local" />
    <option timestep="0.005" integrator="RK4" />
    <default>
        <joint limited="false" armature="0" damping="0" />
        <geom condim="3" conaffinity="0" margin="0" friction="1.0 0.5 0.5" rgba="0.8 0.6 0.4 1" density="100" />
    </default>
    <visual>
        <map znear="0.01" zfar="2500"/>
    </visual>
    <asset>
        <texture type="skybox" builtin="gradient" width="100" height="100" rgb1="1 1 1" rgb2="0 0 0" />
        <texture name="texgeom" type="cube" builtin="flat" mark="cross" width="127" height="1278" rgb1="0.8 0.6 0.4" rgb2="0.8 0.6 0.4" markrgb="1 1 1" random="0.01" />
        <texture name="texplane" type="2d" builtin="checker" rgb1="0.2 0.3 0.4" rgb2="0.1 0.2 0.3" width="100" height="100" />
        <material name="MatPlane" texture="texplane" shininess="0.5" texrepeat="30 30" specular="0.5"  reflectance="0.1" />
        <material name="geom" texture="texgeom" texuniform="true"/>
        <material name="MatObj" shininess="0.4" texrepeat="30 30" specular="0.3"  reflectance="0.05"/>
    </asset>
    <worldbody>
        <light directional="true" cutoff="100" exponent="1" diffuse="1 1 1" specular=".1 .1 .1" pos="0 0 1.3" dir="-0 0 -1.3" />
        <geom name="floor" material="MatPlane" pos="0 0 0" size="40 40 40" type="plane" conaffinity="1" rgba="0.8 0.9 0.8 1" condim="3" />
        <!--  ================= Point ================= /-->
        <!--  Note that the solimp is modified from rllab to prevent the point from going through the wall /-->
        <body name="torso" pos="0 0 0">
            <geom name="pointbody" type="sphere" size="0.5" pos="0 0 0.5" rgba="0.8 0.4 0.1 1" solimp="0.9 0.99 0.001" />
            <joint name="ballx" type="slide" axis="1 0 0" pos="0 0 0" />
            <joint name="bally" type="slide" axis="0 1 0" pos="0 0 0" />
            <joint name="rot" type="hinge" axis="0 0 1" pos="0 0 0" limited="false" damping="2.5"/>
            <camera name="mtdcam1" mode="fixed" pos="0.45 0 0.5" xyaxes="0 -1 0 0 0 1"/>
        </body>
    </worldbody>
    <actuator>
        <velocity joint="ballx" ctrlrange="-10 10" ctrllimited="true" kv="100"/>
        <velocity joint="bally" ctrlrange="-10 10" ctrllimited="true" kv="100"/>
        <velocity joint="rot" ctrlrange="-1.5 1.5" ctrllimited="true" kv="40"/>
    </actuator>
</mujoco>
